[2025-10-27 00:01:34] ERROR django.request log log_response: Internal Server Error: /api/users/register/
Traceback (most recent call last):
  File "C:\Users\Lenovo\Documents\Desktop\epts_project\epts_venv\Lib\site-packages\django\core\handlers\exception.py", line 55, in inner
    response = get_response(request)
  File "C:\Users\Lenovo\Documents\Desktop\epts_project\epts_venv\Lib\site-packages\django\core\handlers\base.py", line 197, in _get_response
    response = wrapped_callback(request, *callback_args, **callback_kwargs)
  File "C:\Users\Lenovo\Documents\Desktop\epts_project\epts_venv\Lib\site-packages\django\views\decorators\csrf.py", line 65, in _view_wrapper
    return view_func(request, *args, **kwargs)
  File "C:\Users\Lenovo\Documents\Desktop\epts_project\epts_venv\Lib\site-packages\django\views\generic\base.py", line 105, in view
    return self.dispatch(request, *args, **kwargs)
           ~~~~~~~~~~~~~^^^^^^^^^^^^^^^^^^^^^^^^^^
  File "C:\Users\Lenovo\Documents\Desktop\epts_project\epts_venv\Lib\site-packages\rest_framework\views.py", line 515, in dispatch
    response = self.handle_exception(exc)
  File "C:\Users\Lenovo\Documents\Desktop\epts_project\epts_venv\Lib\site-packages\rest_framework\views.py", line 475, in handle_exception
    self.raise_uncaught_exception(exc)
    ~~~~~~~~~~~~~~~~~~~~~~~~~~~~~^^^^^
  File "C:\Users\Lenovo\Documents\Desktop\epts_project\epts_venv\Lib\site-packages\rest_framework\views.py", line 486, in raise_uncaught_exception
    raise exc
  File "C:\Users\Lenovo\Documents\Desktop\epts_project\epts_venv\Lib\site-packages\rest_framework\views.py", line 512, in dispatch
    response = handler(request, *args, **kwargs)
  File "C:\Users\Lenovo\Documents\Desktop\epts_project\epts_venv\Lib\site-packages\rest_framework\generics.py", line 194, in post
    return self.create(request, *args, **kwargs)
           ~~~~~~~~~~~^^^^^^^^^^^^^^^^^^^^^^^^^^
  File "C:\Users\Lenovo\Documents\Desktop\epts_project\epts_backend\users\views.py", line 76, in create
    "user": ProfileSerializer(new_user).data,
            ^^^^^^^^^^^^^^^^^^^^^^^^^^^^^^^^
  File "C:\Users\Lenovo\Documents\Desktop\epts_project\epts_venv\Lib\site-packages\rest_framework\serializers.py", line 573, in data
    ret = super().data
          ^^^^^^^^^^^^
  File "C:\Users\Lenovo\Documents\Desktop\epts_project\epts_venv\Lib\site-packages\rest_framework\serializers.py", line 251, in data
    self._data = self.to_representation(self.instance)
                 ~~~~~~~~~~~~~~~~~~~~~~^^^^^^^^^^^^^^^
  File "C:\Users\Lenovo\Documents\Desktop\epts_project\epts_venv\Lib\site-packages\rest_framework\serializers.py", line 540, in to_representation
    ret[field.field_name] = field.to_representation(attribute)
                            ~~~~~~~~~~~~~~~~~~~~~~~^^^^^^^^^^^
  File "C:\Users\Lenovo\Documents\Desktop\epts_project\epts_venv\Lib\site-packages\rest_framework\fields.py", line 1272, in to_representation
    assert not isinstance(value, datetime.datetime), (
           ^^^^^^^^^^^^^^^^^^^^^^^^^^^^^^^^^^^^^^^^
AssertionError: Expected a `date`, but got a `datetime`. Refusing to coerce, as this may mean losing timezone information. Use a custom read-only field and deal with timezone issues explicitly.
